<?xml version='1.0' encoding='utf-8'?>
<robot name="mixed_example" xmlns:xacro="http://www.ros.org/wiki/xacro">
  <!-- Base link for the mixed_example system -->
  <link name="base_link" />
  <!-- Arm_0_Franka arm assembly -->
  <joint name="arm_0_franka_arm_fixed" type="fixed">
    <origin rpy="0 0 0" xyz="-1.0 0.0 0.0" />
    <parent link="base_link" />
    <child link="arm_0_panda_link0" />
    <axis xyz="0 0 0" />
  </joint>
  <link name="arm_0_panda_link0">
    <visual>
      <geometry>
        <mesh filename="../curobo/src/curobo/content/assets/robot/franka_description/meshes/visual/link0.dae" />
      </geometry>
    </visual>
    <collision>
      <geometry>
        <mesh filename="../curobo/src/curobo/content/assets/robot/franka_description/meshes/collision/link0.obj" />
      </geometry>
    </collision>
  </link>
  <link name="arm_0_panda_link1">
    <visual>
      <geometry>
        <mesh filename="../curobo/src/curobo/content/assets/robot/franka_description/meshes/visual/link1.dae" />
      </geometry>
    </visual>
    <collision>
      <geometry>
        <mesh filename="../curobo/src/curobo/content/assets/robot/franka_description/meshes/collision/link1.obj" />
      </geometry>
    </collision>
    <inertial>
      <origin rpy="0 0 0" xyz="0.00033 -0.02204 -0.04762" />
      <mass value="2.797" />
      <inertia ixx="0.0156" ixy="0.0" ixz="0.0" iyy="0.01439" iyz="-0.0024" izz="0.005" />
    </inertial>
  </link>
  <joint name="arm_0_panda_joint1" type="revolute">
    <safety_controller k_position="100.0" k_velocity="40.0" soft_lower_limit="-2.8973" soft_upper_limit="2.8973" />
    <origin rpy="0 0 0" xyz="0 0 0.333" />
    <parent link="arm_0_panda_link0" />
    <child link="arm_0_panda_link1" />
    <axis xyz="0 0 1" />
    <dynamics damping="10.0" />
    <limit effort="87" lower="-2.8973" upper="2.8973" velocity="2.1750" />
  </joint>
  <link name="arm_0_panda_link2">
    <visual>
      <geometry>
        <mesh filename="../curobo/src/curobo/content/assets/robot/franka_description/meshes/visual/link2.dae" />
      </geometry>
    </visual>
    <collision>
      <geometry>
        <mesh filename="../curobo/src/curobo/content/assets/robot/franka_description/meshes/collision/link2.obj" />
      </geometry>
    </collision>
    <inertial>
      <origin rpy="0 0 0" xyz="0.00038 -0.09211 0.01908" />
      <mass value="2.542" />
      <inertia ixx="0.0166" ixy="0.0" ixz="0.0" iyy="0.0046" iyz="0.0035" izz="0.015" />
    </inertial>
  </link>
  <joint name="arm_0_panda_joint2" type="revolute">
    <safety_controller k_position="100.0" k_velocity="40.0" soft_lower_limit="-1.7628" soft_upper_limit="1.7628" />
    <origin rpy="-1.57079632679 0 0" xyz="0 0 0" />
    <parent link="arm_0_panda_link1" />
    <child link="arm_0_panda_link2" />
    <axis xyz="0 0 1" />
    <dynamics damping="10.0" />
    <limit effort="87" lower="-1.7628" upper="1.7628" velocity="2.1750" />
  </joint>
  <link name="arm_0_panda_link3">
    <visual>
      <geometry>
        <mesh filename="../curobo/src/curobo/content/assets/robot/franka_description/meshes/visual/link3.dae" />
      </geometry>
    </visual>
    <collision>
      <geometry>
        <mesh filename="../curobo/src/curobo/content/assets/robot/franka_description/meshes/collision/link3.obj" />
      </geometry>
    </collision>
    <inertial>
      <origin rpy="0 0 0" xyz="0.05152 0.01696 -0.02971" />
      <mass value="2.2513" />
      <inertia ixx="0.006" ixy="0.009" ixz="0.003" iyy="0.0086" iyz="0.009" izz="0.0065" />
    </inertial>
  </link>
  <joint name="arm_0_panda_joint3" type="revolute">
    <safety_controller k_position="100.0" k_velocity="40.0" soft_lower_limit="-2.8973" soft_upper_limit="2.8973" />
    <origin rpy="1.57079632679 0 0" xyz="0 -0.316 0" />
    <parent link="arm_0_panda_link2" />
    <child link="arm_0_panda_link3" />
    <axis xyz="0 0 1" />
    <dynamics damping="10.0" />
    <limit effort="87" lower="-2.8973" upper="2.8973" velocity="2.1750" />
  </joint>
  <link name="arm_0_panda_link4">
    <visual>
      <geometry>
        <mesh filename="../curobo/src/curobo/content/assets/robot/franka_description/meshes/visual/link4.dae" />
      </geometry>
    </visual>
    <collision>
      <geometry>
        <mesh filename="../curobo/src/curobo/content/assets/robot/franka_description/meshes/collision/link4.obj" />
      </geometry>
    </collision>
    <inertial>
      <origin rpy="0 0 0" xyz="-0.05113 0.05825 0.01698" />
      <mass value="2.2037" />
      <inertia ixx="0.0156" ixy="0.0" ixz="0.0" iyy="0.01439" iyz="-0.0024" izz="0.005" />
    </inertial>
  </link>
  <joint name="arm_0_panda_joint4" type="revolute">
    <safety_controller k_position="100.0" k_velocity="40.0" soft_lower_limit="-3.0718" soft_upper_limit="-0.0698" />
    <origin rpy="1.57079632679 0 0" xyz="0.0825 0 0" />
    <parent link="arm_0_panda_link3" />
    <child link="arm_0_panda_link4" />
    <axis xyz="0 0 1" />
    <dynamics damping="10.0" />
    <limit effort="87" lower="-3.0718" upper="-0.0698" velocity="2.1750" />
  </joint>
  <link name="arm_0_panda_link5">
    <visual>
      <geometry>
        <mesh filename="../curobo/src/curobo/content/assets/robot/franka_description/meshes/visual/link5.dae" />
      </geometry>
    </visual>
    <collision>
      <geometry>
        <mesh filename="../curobo/src/curobo/content/assets/robot/franka_description/meshes/collision/link5.obj" />
      </geometry>
    </collision>
    <inertial>
      <origin rpy="0 0 0" xyz="-0.00005 0.03730 -0.09280" />
      <mass value="2.2855" />
      <inertia ixx="0.02297014781" ixy="0.0" ixz="0.0" iyy="0.02095060919" iyz="0.00382345782" izz="0.00430606551" />
    </inertial>
  </link>
  <joint name="arm_0_panda_joint5" type="revolute">
    <safety_controller k_position="100.0" k_velocity="40.0" soft_lower_limit="-2.8973" soft_upper_limit="2.8973" />
    <origin rpy="-1.57079632679 0 0" xyz="-0.0825 0.384 0" />
    <parent link="arm_0_panda_link4" />
    <child link="arm_0_panda_link5" />
    <axis xyz="0 0 1" />
    <dynamics damping="10.0" />
    <limit effort="12" lower="-2.8973" upper="2.8973" velocity="2.6100" />
  </joint>
  <link name="arm_0_panda_link6">
    <visual>
      <geometry>
        <mesh filename="../curobo/src/curobo/content/assets/robot/franka_description/meshes/visual/link6.dae" />
      </geometry>
    </visual>
    <collision>
      <geometry>
        <mesh filename="../curobo/src/curobo/content/assets/robot/franka_description/meshes/collision/link6.obj" />
      </geometry>
    </collision>
    <inertial>
      <origin rpy="0 0 0" xyz="0.06572 -0.00371 0.00153" />
      <mass value="1.353" />
      <inertia ixx="0.00087964522" ixy="-0.00021487814" ixz="-0.00011911662" iyy="0.00277796968" iyz="0.00001274322" izz="0.00286701969" />
    </inertial>
  </link>
  <joint name="arm_0_panda_joint6" type="revolute">
    <safety_controller k_position="100.0" k_velocity="40.0" soft_lower_limit="-0.0175" soft_upper_limit="3.7525" />
    <origin rpy="1.57079632679 0 0" xyz="0 0 0" />
    <parent link="arm_0_panda_link5" />
    <child link="arm_0_panda_link6" />
    <axis xyz="0 0 1" />
    <dynamics damping="10.0" />
    <limit effort="12" lower="-0.0175" upper="3.7525" velocity="2.6100" />
  </joint>
  <link name="arm_0_panda_link7">
    <visual>
      <geometry>
        <mesh filename="../curobo/src/curobo/content/assets/robot/franka_description/meshes/visual/link7.dae" />
      </geometry>
    </visual>
    <collision>
      <geometry>
        <mesh filename="../curobo/src/curobo/content/assets/robot/franka_description/meshes/collision/link7.obj" />
      </geometry>
    </collision>
    <inertial>
      <origin rpy="0 0 0" xyz="0.00089 -0.00044 0.05491" />
      <mass value="0.35973" />
      <inertia ixx="0.00019541063" ixy="0.00000165231" ixz="0.00000148826" iyy="0.00019210361" iyz="-0.00000131132" izz="0.00017936256" />
    </inertial>
  </link>
  <joint name="arm_0_panda_joint7" type="revolute">
    <safety_controller k_position="100.0" k_velocity="40.0" soft_lower_limit="-2.8973" soft_upper_limit="2.8973" />
    <origin rpy="1.57079632679 0 0" xyz="0.088 0 0" />
    <parent link="arm_0_panda_link6" />
    <child link="arm_0_panda_link7" />
    <axis xyz="0 0 1" />
    <dynamics damping="10.0" />
    <limit effort="12" lower="-2.8973" upper="2.8973" velocity="2.6100" />
  </joint>
  <link name="arm_0_panda_link8" />
  <joint name="arm_0_panda_joint8" type="fixed">
    <origin rpy="0 0 0" xyz="0 0 0.107" />
    <parent link="arm_0_panda_link7" />
    <child link="arm_0_panda_link8" />
    <axis xyz="0 0 0" />
  </joint>
  <joint name="arm_0_panda_hand_joint" type="fixed">
    <parent link="arm_0_panda_link8" />
    <child link="arm_0_panda_hand" />
    <origin rpy="0 0 -0.785398163397" xyz="0 0 0" />
  </joint>
  <link name="arm_0_panda_hand">
    <visual>
      <geometry>
        <mesh filename="../curobo/src/curobo/content/assets/robot/franka_description/meshes/visual/hand.dae" />
      </geometry>
    </visual>
    <collision>
      <geometry>
        <mesh filename="../curobo/src/curobo/content/assets/robot/franka_description/meshes/collision/hand.obj" />
      </geometry>
    </collision>
  </link>
  <link name="arm_0_panda_leftfinger">
    <visual>
      <geometry>
        <mesh filename="../curobo/src/curobo/content/assets/robot/franka_description/meshes/visual/finger.dae" />
      </geometry>
    </visual>
    <collision>
      <geometry>
        <mesh filename="../curobo/src/curobo/content/assets/robot/franka_description/meshes/collision/finger.obj" />
      </geometry>
    </collision>
  </link>
  <link name="arm_0_panda_rightfinger">
    <visual>
      <origin rpy="0 0 3.14159265359" xyz="0 0 0" />
      <geometry>
        <mesh filename="../curobo/src/curobo/content/assets/robot/franka_description/meshes/visual/finger.dae" />
      </geometry>
    </visual>
    <collision>
      <origin rpy="0 0 3.14159265359" xyz="0 0 0" />
      <geometry>
        <mesh filename="../curobo/src/curobo/content/assets/robot/franka_description/meshes/collision/finger.obj" />
      </geometry>
    </collision>
  </link>
  <joint name="arm_0_panda_finger_joint1" type="prismatic">
    <parent link="arm_0_panda_hand" />
    <child link="arm_0_panda_leftfinger" />
    <origin rpy="0 0 0" xyz="0 0 0.0584" />
    <axis xyz="0 1 0" />
    <dynamics damping="10.0" />
    <limit effort="20" lower="0.0" upper="0.04" velocity="0.2" />
  </joint>
  <joint name="arm_0_panda_finger_joint2" type="prismatic">
    <parent link="arm_0_panda_hand" />
    <child link="arm_0_panda_rightfinger" />
    <origin rpy="0 0 0" xyz="0 0 0.0584" />
    <axis xyz="0 -1 0" />
    <dynamics damping="10.0" />
    <limit effort="20" lower="0.0" upper="0.04" velocity="0.2" />
  </joint>
  <link name="arm_0_ee_link" />
  <joint name="arm_0_ee_fixed_joint" type="fixed">
    <parent link="arm_0_panda_hand" />
    <child link="arm_0_ee_link" />
    <origin rpy="0 0.0 0" xyz="0.0 0. 0.1" />
  </joint>
  <link name="arm_0_right_gripper">
    <inertial>
      <mass value="0.01" />
      <inertia ixx="0.0001" ixy="0.0" ixz="0.0" iyy="0.0001" iyz="0.0" izz="0.0001" />
      <origin rpy="0 0 0" xyz="0 0 0" />
    </inertial>
  </link>
  <joint name="arm_0_right_gripper" type="fixed">
    <origin rpy="0 0 2.35619449019" xyz="0 0 0.207" />
    <axis xyz="0 0 1" />
    <parent link="arm_0_panda_link7" />
    <child link="arm_0_right_gripper" />
  </joint>
  <!-- Arm_1_Ur5E arm assembly -->
  <joint name="arm_1_ur5e_arm_fixed" type="fixed">
    <origin rpy="0 0 0" xyz="0.0 0.0 0.0" />
    <parent link="base_link" />
    <child link="arm_1_base_link_inertia" />
    <axis xyz="0 0 0" />
  </joint>
  <link name="arm_1_base_link_inertia">
    <visual>
      <origin rpy="0 0 3.141592653589793" xyz="0 0 0" />
      <geometry>
        <mesh filename="../curobo/src/curobo/content/assets/robot/ur_description/meshes/ur5e/visual/base.dae" />
      </geometry>
      <material name="LightGrey">
        <color rgba="0.7 0.7 0.7 1.0" />
      </material>
    </visual>
    <collision>
      <origin rpy="0 0 3.141592653589793" xyz="0 0 0" />
      <geometry>
        <mesh filename="../curobo/src/curobo/content/assets/robot/ur_description/meshes/ur5e/collision/base.stl" />
      </geometry>
    </collision>
    <inertial>
      <mass value="4.0" />
      <origin rpy="0 0 0" xyz="0 0 0" />
      <inertia ixx="0.00443333156" ixy="0.0" ixz="0.0" iyy="0.00443333156" iyz="0.0" izz="0.0072" />
    </inertial>
  </link>
  <link name="arm_1_shoulder_link">
    <visual>
      <origin rpy="0 0 3.141592653589793" xyz="0 0 0" />
      <geometry>
        <mesh filename="../curobo/src/curobo/content/assets/robot/ur_description/meshes/ur5e/visual/shoulder.dae" />
      </geometry>
      <material name="LightGrey">
        <color rgba="0.7 0.7 0.7 1.0" />
      </material>
    </visual>
    <collision>
      <origin rpy="0 0 3.141592653589793" xyz="0 0 0" />
      <geometry>
        <mesh filename="../curobo/src/curobo/content/assets/robot/ur_description/meshes/ur5e/collision/shoulder.stl" />
      </geometry>
    </collision>
    <inertial>
      <mass value="3.7" />
      <origin rpy="0 0 0" xyz="0 0 0" />
      <inertia ixx="0.010267495893" ixy="0.0" ixz="0.0" iyy="0.010267495893" iyz="0.0" izz="0.00666" />
    </inertial>
  </link>
  <link name="arm_1_upper_arm_link">
    <visual>
      <origin rpy="1.5707963267948966 0 -1.5707963267948966" xyz="0 0 0.138" />
      <geometry>
        <mesh filename="../curobo/src/curobo/content/assets/robot/ur_description/meshes/ur5e/visual/upperarm.dae" />
      </geometry>
      <material name="LightGrey">
        <color rgba="0.7 0.7 0.7 1.0" />
      </material>
    </visual>
    <collision>
      <origin rpy="1.5707963267948966 0 -1.5707963267948966" xyz="0 0 0.138" />
      <geometry>
        <mesh filename="../curobo/src/curobo/content/assets/robot/ur_description/meshes/ur5e/collision/upperarm.stl" />
      </geometry>
    </collision>
    <inertial>
      <mass value="8.393" />
      <origin rpy="0 1.5707963267948966 0" xyz="-0.2125 0.0 0.138" />
      <inertia ixx="0.1338857818623325" ixy="0.0" ixz="0.0" iyy="0.1338857818623325" iyz="0.0" izz="0.0151074" />
    </inertial>
  </link>
  <link name="arm_1_forearm_link">
    <visual>
      <origin rpy="1.5707963267948966 0 -1.5707963267948966" xyz="0 0 0.007" />
      <geometry>
        <mesh filename="../curobo/src/curobo/content/assets/robot/ur_description/meshes/ur5e/visual/forearm.dae" />
      </geometry>
      <material name="LightGrey">
        <color rgba="0.7 0.7 0.7 1.0" />
      </material>
    </visual>
    <collision>
      <origin rpy="1.5707963267948966 0 -1.5707963267948966" xyz="0 0 0.007" />
      <geometry>
        <mesh filename="../curobo/src/curobo/content/assets/robot/ur_description/meshes/ur5e/collision/forearm.stl" />
      </geometry>
    </collision>
    <inertial>
      <mass value="2.275" />
      <origin rpy="0 1.5707963267948966 0" xyz="-0.1961 0.0 0.007" />
      <inertia ixx="0.031209355099586295" ixy="0.0" ixz="0.0" iyy="0.031209355099586295" iyz="0.0" izz="0.004095" />
    </inertial>
  </link>
  <link name="arm_1_wrist_1_link">
    <visual>
      <origin rpy="1.5707963267948966 0 0" xyz="0 0 -0.127" />
      <geometry>
        <mesh filename="../curobo/src/curobo/content/assets/robot/ur_description/meshes/ur5e/visual/wrist1.dae" />
      </geometry>
      <material name="LightGrey">
        <color rgba="0.7 0.7 0.7 1.0" />
      </material>
    </visual>
    <collision>
      <origin rpy="1.5707963267948966 0 0" xyz="0 0 -0.127" />
      <geometry>
        <mesh filename="../curobo/src/curobo/content/assets/robot/ur_description/meshes/ur5e/collision/wrist1.stl" />
      </geometry>
    </collision>
    <inertial>
      <mass value="1.219" />
      <origin rpy="0 0 0" xyz="0 0 0" />
      <inertia ixx="0.0025598989760400002" ixy="0.0" ixz="0.0" iyy="0.0025598989760400002" iyz="0.0" izz="0.0021942" />
    </inertial>
  </link>
  <link name="arm_1_wrist_2_link">
    <visual>
      <origin rpy="0 0 0" xyz="0 0 -0.0997" />
      <geometry>
        <mesh filename="../curobo/src/curobo/content/assets/robot/ur_description/meshes/ur5e/visual/wrist2.dae" />
      </geometry>
      <material name="LightGrey">
        <color rgba="0.7 0.7 0.7 1.0" />
      </material>
    </visual>
    <collision>
      <origin rpy="0 0 0" xyz="0 0 -0.0997" />
      <geometry>
        <mesh filename="../curobo/src/curobo/content/assets/robot/ur_description/meshes/ur5e/collision/wrist2.stl" />
      </geometry>
    </collision>
    <inertial>
      <mass value="1.219" />
      <origin rpy="0 0 0" xyz="0 0 0" />
      <inertia ixx="0.0025598989760400002" ixy="0.0" ixz="0.0" iyy="0.0025598989760400002" iyz="0.0" izz="0.0021942" />
    </inertial>
  </link>
  <link name="arm_1_wrist_3_link">
    <visual>
      <origin rpy="1.5707963267948966 0 0" xyz="0 0 -0.0989" />
      <geometry>
        <mesh filename="../curobo/src/curobo/content/assets/robot/ur_description/meshes/ur5e/visual/wrist3.dae" />
      </geometry>
      <material name="LightGrey">
        <color rgba="0.7 0.7 0.7 1.0" />
      </material>
    </visual>
    <collision>
      <origin rpy="1.5707963267948966 0 0" xyz="0 0 -0.0989" />
      <geometry>
        <mesh filename="../curobo/src/curobo/content/assets/robot/ur_description/meshes/ur5e/collision/wrist3.stl" />
      </geometry>
    </collision>
    <inertial>
      <mass value="0.1879" />
      <origin rpy="0 0 0" xyz="0.0 0.0 -0.0229" />
      <inertia ixx="9.890410052167731e-05" ixy="0.0" ixz="0.0" iyy="9.890410052167731e-05" iyz="0.0" izz="0.0001321171875" />
    </inertial>
  </link>
  <joint name="arm_1_base_link-base_link_inertia" type="fixed">
    <parent link="arm_1_base_link" />
    <child link="arm_1_base_link_inertia" />
    <origin rpy="0 0 3.141592653589793" xyz="0 0 0" />
  </joint>
  <joint name="arm_1_shoulder_pan_joint" type="revolute">
    <parent link="arm_1_base_link_inertia" />
    <child link="arm_1_shoulder_link" />
    <origin rpy="0 0 0" xyz="0 0 0.1625" />
    <axis xyz="0 0 1" />
    <limit effort="150.0" lower="-6.283185307179586" upper="6.283185307179586" velocity="3.141592653589793" />
    <dynamics damping="0" friction="0" />
  </joint>
  <joint name="arm_1_shoulder_lift_joint" type="revolute">
    <parent link="arm_1_shoulder_link" />
    <child link="arm_1_upper_arm_link" />
    <origin rpy="1.570796327 0 0" xyz="0 0 0" />
    <axis xyz="0 0 1" />
    <limit effort="150.0" lower="-6.283185307179586" upper="6.283185307179586" velocity="3.141592653589793" />
    <dynamics damping="0" friction="0" />
  </joint>
  <joint name="arm_1_elbow_joint" type="revolute">
    <parent link="arm_1_upper_arm_link" />
    <child link="arm_1_forearm_link" />
    <origin rpy="0 0 0" xyz="-0.425 0 0" />
    <axis xyz="0 0 1" />
    <limit effort="150.0" lower="-3.141592653589793" upper="3.141592653589793" velocity="3.141592653589793" />
    <dynamics damping="0" friction="0" />
  </joint>
  <joint name="arm_1_wrist_1_joint" type="revolute">
    <parent link="arm_1_forearm_link" />
    <child link="arm_1_wrist_1_link" />
    <origin rpy="0 0 0" xyz="-0.3922 0 0.1333" />
    <axis xyz="0 0 1" />
    <limit effort="28.0" lower="-6.283185307179586" upper="6.283185307179586" velocity="3.141592653589793" />
    <dynamics damping="0" friction="0" />
  </joint>
  <joint name="arm_1_wrist_2_joint" type="revolute">
    <parent link="arm_1_wrist_1_link" />
    <child link="arm_1_wrist_2_link" />
    <origin rpy="1.570796327 0 0" xyz="0 -0.0997 -2.044881182297852e-11" />
    <axis xyz="0 0 1" />
    <limit effort="28.0" lower="-6.283185307179586" upper="6.283185307179586" velocity="3.141592653589793" />
    <dynamics damping="0" friction="0" />
  </joint>
  <joint name="arm_1_wrist_3_joint" type="revolute">
    <parent link="arm_1_wrist_2_link" />
    <child link="arm_1_wrist_3_link" />
    <origin rpy="1.570796326589793 3.141592653589793 3.141592653589793" xyz="0 0.0996 -2.042830148012698e-11" />
    <axis xyz="0 0 1" />
    <limit effort="28.0" lower="-6.283185307179586" upper="6.283185307179586" velocity="3.141592653589793" />
    <dynamics damping="0" friction="0" />
  </joint>
  <link name="arm_1_base" />
  <joint name="arm_1_base_link-base_fixed_joint" type="fixed">
    <origin rpy="0 0 3.141592653589793" xyz="0 0 0" />
    <parent link="arm_1_base_link" />
    <child link="arm_1_base" />
  </joint>
  <link name="arm_1_flange" />
  <joint name="arm_1_wrist_3-flange" type="fixed">
    <parent link="arm_1_wrist_3_link" />
    <child link="arm_1_flange" />
    <origin rpy="0 -1.5707963267948966 -1.5707963267948966" xyz="0 0 0" />
  </joint>
  <link name="arm_1_tool0" />
  <joint name="arm_1_flange-tool0" type="fixed">
    <origin rpy="1.5707963267948966 0 1.5707963267948966" xyz="0 0 0" />
    <parent link="arm_1_flange" />
    <child link="arm_1_tool0" />
  </joint>
  <!-- Arm_2_Kinova arm assembly -->
  <joint name="arm_2_kinova_arm_fixed" type="fixed">
    <origin rpy="0 0 0" xyz="1.0 0.0 0.0" />
    <parent link="base_link" />
    <child link="arm_2_base_link" />
    <axis xyz="0 0 0" />
  </joint>
  <link name="arm_2_base_link">
    <inertial>
      <origin rpy="0 0 0" xyz="-0.000648 -0.000166 0.084487" />
      <mass value="1.697" />
      <inertia ixx="0.004622" ixy="9E-06" ixz="6E-05" iyy="0.004495" iyz="9E-06" izz="0.002079" />
    </inertial>
    <visual>
      <origin rpy="0 0 0" xyz="0 0 0" />
      <geometry>
        <mesh filename="../curobo/src/curobo/content/assets/robot/kinova/kortex_description/arms/gen3/7dof/meshes/base_link.STL" />
      </geometry>
      <material name="">
        <color rgba="0.75294 0.75294 0.75294 1" />
      </material>
    </visual>
    <collision>
      <origin rpy="0 0 0" xyz="0 0 0" />
      <geometry>
        <mesh filename="../curobo/src/curobo/content/assets/robot/kinova/kortex_description/arms/gen3/7dof/meshes/base_link.STL" />
      </geometry>
    </collision>
  </link>
  <link name="arm_2_shoulder_link">
    <inertial>
      <origin rpy="0 0 0" xyz="-2.3E-05 -0.010364 -0.07336" />
      <mass value="1.3773" />
      <inertia ixx="0.00457" ixy="1E-06" ixz="2E-06" iyy="0.004831" iyz="0.000448" izz="0.001409" />
    </inertial>
    <visual>
      <origin rpy="0 0 0" xyz="0 0 0" />
      <geometry>
        <mesh filename="../curobo/src/curobo/content/assets/robot/kinova/kortex_description/arms/gen3/7dof/meshes/shoulder_link.STL" />
      </geometry>
      <material name="">
        <color rgba="0.75294 0.75294 0.75294 1" />
      </material>
    </visual>
    <collision>
      <origin rpy="0 0 0" xyz="0 0 0" />
      <geometry>
        <mesh filename="../curobo/src/curobo/content/assets/robot/kinova/kortex_description/arms/gen3/7dof/meshes/shoulder_link.STL" />
      </geometry>
    </collision>
  </link>
  <joint name="arm_2_joint_1" type="revolute">
    <origin rpy="3.1416 2.7629E-18 -4.9305E-36" xyz="0 0 0.15643" />
    <parent link="arm_2_base_link" />
    <child link="arm_2_shoulder_link" />
    <axis xyz="0 0 1" />
    <limit effort="39" lower="-6.0" upper="6.0" velocity="1.3963" />
  </joint>
  <link name="arm_2_half_arm_1_link">
    <inertial>
      <origin rpy="0 0 0" xyz="-4.4E-05 -0.09958 -0.013278" />
      <mass value="1.1636" />
      <inertia ixx="0.011088" ixy="5E-06" ixz="0" iyy="0.001072" iyz="-0.000691" izz="0.011255" />
    </inertial>
    <visual>
      <origin rpy="0 0 0" xyz="0 0 0" />
      <geometry>
        <mesh filename="../curobo/src/curobo/content/assets/robot/kinova/kortex_description/arms/gen3/7dof/meshes/half_arm_1_link.STL" />
      </geometry>
      <material name="">
        <color rgba="0.75294 0.75294 0.75294 1" />
      </material>
    </visual>
    <collision>
      <origin rpy="0 0 0" xyz="0 0 0" />
      <geometry>
        <mesh filename="../curobo/src/curobo/content/assets/robot/kinova/kortex_description/arms/gen3/7dof/meshes/half_arm_1_link.STL" />
      </geometry>
    </collision>
  </link>
  <joint name="arm_2_joint_2" type="revolute">
    <origin rpy="1.5708 2.1343E-17 -1.1102E-16" xyz="0 0.005375 -0.12838" />
    <parent link="arm_2_shoulder_link" />
    <child link="arm_2_half_arm_1_link" />
    <axis xyz="0 0 1" />
    <limit effort="39" lower="-2.41" upper="2.41" velocity="1.3963" />
  </joint>
  <link name="arm_2_half_arm_2_link">
    <inertial>
      <origin rpy="0 0 0" xyz="-4.4E-05 -0.006641 -0.117892" />
      <mass value="1.1636" />
      <inertia ixx="0.010932" ixy="0" ixz="-7E-06" iyy="0.011127" iyz="0.000606" izz="0.001043" />
    </inertial>
    <visual>
      <origin rpy="0 0 0" xyz="0 0 0" />
      <geometry>
        <mesh filename="../curobo/src/curobo/content/assets/robot/kinova/kortex_description/arms/gen3/7dof/meshes/half_arm_2_link.STL" />
      </geometry>
      <material name="">
        <color rgba="0.75294 0.75294 0.75294 1" />
      </material>
    </visual>
    <collision>
      <origin rpy="0 0 0" xyz="0 0 0" />
      <geometry>
        <mesh filename="../curobo/src/curobo/content/assets/robot/kinova/kortex_description/arms/gen3/7dof/meshes/half_arm_2_link.STL" />
      </geometry>
    </collision>
  </link>
  <joint name="arm_2_joint_3" type="revolute">
    <origin rpy="-1.5708 1.2326E-32 -2.9122E-16" xyz="0 -0.21038 -0.006375" />
    <parent link="arm_2_half_arm_1_link" />
    <child link="arm_2_half_arm_2_link" />
    <axis xyz="0 0 1" />
    <limit effort="39" lower="-6.0" upper="6.0" velocity="1.3963" />
  </joint>
  <link name="arm_2_forearm_link">
    <inertial>
      <origin rpy="0 0 0" xyz="-1.8E-05 -0.075478 -0.015006" />
      <mass value="0.9302" />
      <inertia ixx="0.008147" ixy="-1E-06" ixz="0" iyy="0.000631" iyz="-0.0005" izz="0.008316" />
    </inertial>
    <visual>
      <origin rpy="0 0 0" xyz="0 0 0" />
      <geometry>
        <mesh filename="../curobo/src/curobo/content/assets/robot/kinova/kortex_description/arms/gen3/7dof/meshes/forearm_link.STL" />
      </geometry>
      <material name="">
        <color rgba="0.75294 0.75294 0.75294 1" />
      </material>
    </visual>
    <collision>
      <origin rpy="0 0 0" xyz="0 0 0" />
      <geometry>
        <mesh filename="../curobo/src/curobo/content/assets/robot/kinova/kortex_description/arms/gen3/7dof/meshes/forearm_link.STL" />
      </geometry>
    </collision>
  </link>
  <joint name="arm_2_joint_4" type="revolute">
    <origin rpy="1.5708 -6.6954E-17 -1.6653E-16" xyz="0 0.006375 -0.21038" />
    <parent link="arm_2_half_arm_2_link" />
    <child link="arm_2_forearm_link" />
    <axis xyz="0 0 1" />
    <limit effort="39" lower="-2.66" upper="2.66" velocity="1.3963" />
  </joint>
  <link name="arm_2_spherical_wrist_1_link">
    <inertial>
      <origin rpy="0 0 0" xyz="1E-06 -0.009432 -0.063883" />
      <mass value="0.6781" />
      <inertia ixx="0.001596" ixy="0" ixz="0" iyy="0.001607" iyz="0.000256" izz="0.000399" />
    </inertial>
    <visual>
      <origin rpy="0 0 0" xyz="0 0 0" />
      <geometry>
        <mesh filename="../curobo/src/curobo/content/assets/robot/kinova/kortex_description/arms/gen3/7dof/meshes/spherical_wrist_1_link.STL" />
      </geometry>
      <material name="">
        <color rgba="0.75294 0.75294 0.75294 1" />
      </material>
    </visual>
    <collision>
      <origin rpy="0 0 0" xyz="0 0 0" />
      <geometry>
        <mesh filename="../curobo/src/curobo/content/assets/robot/kinova/kortex_description/arms/gen3/7dof/meshes/spherical_wrist_1_link.STL" />
      </geometry>
    </collision>
  </link>
  <joint name="arm_2_joint_5" type="revolute">
    <origin rpy="-1.5708 2.2204E-16 -6.373E-17" xyz="0 -0.20843 -0.006375" />
    <parent link="arm_2_forearm_link" />
    <child link="arm_2_spherical_wrist_1_link" />
    <axis xyz="0 0 1" />
    <limit effort="9" lower="-6.0" upper="6.0" velocity="1.2218" />
  </joint>
  <link name="arm_2_spherical_wrist_2_link">
    <inertial>
      <origin rpy="0 0 0" xyz="1E-06 -0.045483 -0.00965" />
      <mass value="0.6781" />
      <inertia ixx="0.001641" ixy="0" ixz="0" iyy="0.00041" iyz="-0.000278" izz="0.001641" />
    </inertial>
    <visual>
      <origin rpy="0 0 0" xyz="0 0 0" />
      <geometry>
        <mesh filename="../curobo/src/curobo/content/assets/robot/kinova/kortex_description/arms/gen3/7dof/meshes/spherical_wrist_2_link.STL" />
      </geometry>
      <material name="">
        <color rgba="0.75294 0.75294 0.75294 1" />
      </material>
    </visual>
    <collision>
      <origin rpy="0 0 0" xyz="0 0 0" />
      <geometry>
        <mesh filename="../curobo/src/curobo/content/assets/robot/kinova/kortex_description/arms/gen3/7dof/meshes/spherical_wrist_2_link.STL" />
      </geometry>
    </collision>
  </link>
  <joint name="arm_2_joint_6" type="revolute">
    <origin rpy="1.5708 9.2076E-28 -8.2157E-15" xyz="0 0.00017505 -0.10593" />
    <parent link="arm_2_spherical_wrist_1_link" />
    <child link="arm_2_spherical_wrist_2_link" />
    <axis xyz="0 0 1" />
    <limit effort="9" lower="-2.23" upper="2.23" velocity="1.2218" />
  </joint>
  <link name="arm_2_bracelet_link">
    <inertial>
      <origin rpy="0 0 0" xyz="0.000281 0.011402 -0.029798" />
      <mass value="0.5" />
      <inertia ixx="0.000587" ixy="3E-06" ixz="3E-06" iyy="0.000369" iyz="-0.000118" izz="0.000609" />
    </inertial>
    <visual>
      <origin rpy="0 0 0" xyz="0 0 0" />
      <geometry>
        <mesh filename="../curobo/src/curobo/content/assets/robot/kinova/kortex_description/arms/gen3/7dof/meshes/bracelet_with_vision_link.STL" />
      </geometry>
      <material name="">
        <color rgba="0.75294 0.75294 0.75294 1" />
      </material>
    </visual>
    <collision>
      <origin rpy="0 0 0" xyz="0 0 0" />
      <geometry>
        <mesh filename="../curobo/src/curobo/content/assets/robot/kinova/kortex_description/arms/gen3/7dof/meshes/bracelet_with_vision_link.STL" />
      </geometry>
    </collision>
  </link>
  <joint name="arm_2_joint_7" type="revolute">
    <origin rpy="-1.5708 -5.5511E-17 9.6396E-17" xyz="0 -0.10593 -0.00017505" />
    <parent link="arm_2_spherical_wrist_2_link" />
    <child link="arm_2_bracelet_link" />
    <axis xyz="0 0 1" />
    <limit effort="9" lower="-6.0" upper="6.0" velocity="1.2218" />
  </joint>
  <link name="arm_2_end_effector_link" />
  <joint name="arm_2_end_effector" type="fixed">
    <origin rpy="3.14159265358979 1.09937075168372E-32 0" xyz="0 0 -0.0615250000000001" />
    <parent link="arm_2_bracelet_link" />
    <child link="arm_2_end_effector_link" />
    <axis xyz="0 0 0" />
  </joint>
  <link name="arm_2_camera_link" />
  <joint name="arm_2_camera_module" type="fixed">
    <origin rpy="3.14159265358979 3.14159265358979 0" xyz="0 0.05639 -0.00305" />
    <parent link="arm_2_end_effector_link" />
    <child link="arm_2_camera_link" />
  </joint>
  <link name="arm_2_camera_depth_frame" />
  <joint name="arm_2_depth_module" type="fixed">
    <origin rpy="3.14159265358979 3.14159265358979 0" xyz="0.0275 0.066 -0.00305" />
    <parent link="arm_2_end_effector_link" />
    <child link="arm_2_camera_depth_frame" />
  </joint>
  <link name="arm_2_camera_color_frame" />
  <joint name="arm_2_color_module" type="fixed">
    <origin rpy="3.14159265358979 3.14159265358979 0" xyz="0 0.05639 -0.00305" />
    <parent link="arm_2_end_effector_link" />
    <child link="arm_2_camera_color_frame" />
  </joint>
  <link name="arm_2_tool_frame" />
  <joint name="arm_2_tool_frame_joint" type="fixed">
    <origin rpy="0 0 0" xyz="0 0 0.120" />
    <parent link="arm_2_end_effector_link" />
    <child link="arm_2_tool_frame" />
    <axis xyz="0 0 0" />
  </joint>
  <joint name="arm_2_gripper_base_joint" type="fixed">
    <parent link="arm_2_end_effector_link" />
    <child link="arm_2_robotiq_arg2f_base_link" />
    <origin rpy="0.0 0.0 1.57" xyz="0.0 0.0 0.0" />
  </joint>
  <link name="arm_2_robotiq_arg2f_base_link">
    <inertial>
      <origin rpy="0 0 0" xyz="8.625E-08 -4.6583E-06 0.03145" />
      <mass value="0.22652" />
      <inertia ixx="0.00020005" ixy="-4.2442E-10" ixz="-2.9069E-10" iyy="0.00017832" iyz="-3.4402E-08" izz="0.00013478" />
    </inertial>
    <visual>
      <origin rpy="0 0 0" xyz="0 0 0" />
      <geometry>
        <mesh filename="../curobo/src/curobo/content/assets/robot/kinova/kortex_description/grippers/robotiq_2f_85/meshes/collision/robotiq_arg2f_base_link.stl" />
      </geometry>
      <material name="">
        <color rgba="0.1 0.1 0.1 1" />
      </material>
    </visual>
    <collision>
      <origin rpy="0 0 0" xyz="0 0 0" />
      <geometry>
        <mesh filename="../curobo/src/curobo/content/assets/robot/kinova/kortex_description/grippers/robotiq_2f_85/meshes/collision/robotiq_arg2f_base_link.stl" />
      </geometry>
    </collision>
  </link>
  <link name="arm_2_left_outer_knuckle">
    <inertial>
      <origin rpy="0 0 0" xyz="-0.000200000000003065 0.0199435877845359 0.0292245259211331" />
      <mass value="0.00853198276973456" />
      <inertia ixx="2.89328108496468E-06" ixy="-1.57935047237397E-19" ixz="-1.93980378593255E-19" iyy="1.86719750325683E-06" iyz="-1.21858577871576E-06" izz="1.21905238907251E-06" />
    </inertial>
    <visual>
      <origin rpy="0 0 0" xyz="0 0 0" />
      <geometry>
        <mesh filename="../curobo/src/curobo/content/assets/robot/kinova/kortex_description/grippers/robotiq_2f_85/meshes/visual/robotiq_arg2f_85_outer_knuckle.dae" scale="0.001 0.001 0.001" />
      </geometry>
      <material name="">
        <color rgba="0.792156862745098 0.819607843137255 0.933333333333333 1" />
      </material>
    </visual>
    <collision>
      <origin rpy="0 0 0" xyz="0 0 0" />
      <geometry>
        <mesh filename="../curobo/src/curobo/content/assets/robot/kinova/kortex_description/grippers/robotiq_2f_85/meshes/collision/robotiq_arg2f_85_outer_knuckle.dae" scale="0.001 0.001 0.001" />
      </geometry>
    </collision>
  </link>
  <link name="arm_2_left_outer_finger">
    <inertial>
      <origin rpy="0 0 0" xyz="0.00030115855001899 0.0373907951953854 -0.0208027427000385" />
      <mass value="0.022614240507152" />
      <inertia ixx="1.52518312458174E-05" ixy="9.76583423954399E-10" ixz="-5.43838577022588E-10" iyy="6.17694243867776E-06" iyz="6.78636130740228E-06" izz="1.16494917907219E-05" />
    </inertial>
    <visual>
      <origin rpy="0 0 0" xyz="0 0 0" />
      <geometry>
        <mesh filename="../curobo/src/curobo/content/assets/robot/kinova/kortex_description/grippers/robotiq_2f_85/meshes/visual/robotiq_arg2f_85_outer_finger.dae" scale="0.001 0.001 0.001" />
      </geometry>
      <material name="">
        <color rgba="0.1 0.1 0.1 1" />
      </material>
    </visual>
    <collision>
      <origin rpy="0 0 0" xyz="0 0 0" />
      <geometry>
        <mesh filename="../curobo/src/curobo/content/assets/robot/kinova/kortex_description/grippers/robotiq_2f_85/meshes/collision/robotiq_arg2f_85_outer_finger.dae" scale="0.001 0.001 0.001" />
      </geometry>
    </collision>
  </link>
  <link name="arm_2_left_inner_finger">
    <inertial>
      <origin rpy="0 0 0" xyz="0.000299999999999317 0.0160078233491243 -0.0136945669206257" />
      <mass value="0.0104003125914103" />
      <inertia ixx="2.71909453810972E-06" ixy="1.35402465472579E-21" ixz="-7.1817349065269E-22" iyy="7.69100314106116E-07" iyz="6.74715432769696E-07" izz="2.30315190420171E-06" />
    </inertial>
    <visual>
      <origin rpy="0 0 0" xyz="0 0 0" />
      <geometry>
        <mesh filename="../curobo/src/curobo/content/assets/robot/kinova/kortex_description/grippers/robotiq_2f_85/meshes/visual/robotiq_arg2f_85_inner_finger.dae" scale="0.001 0.001 0.001" />
      </geometry>
      <material name="">
        <color rgba="0.1 0.1 0.1 1" />
      </material>
    </visual>
    <collision>
      <origin rpy="0 0 0" xyz="0 0 0" />
      <geometry>
        <mesh filename="../curobo/src/curobo/content/assets/robot/kinova/kortex_description/grippers/robotiq_2f_85/meshes/collision/robotiq_arg2f_85_inner_finger.dae" scale="0.001 0.001 0.001" />
      </geometry>
    </collision>
  </link>
  <link name="arm_2_left_inner_finger_pad">
    <visual>
      <origin rpy="0 0 0" xyz="0 0 0" />
      <geometry>
        <box size="0.022 0.00635 0.0375" />
      </geometry>
      <material name="">
        <color rgba="0.9 0.9 0.9 1" />
      </material>
    </visual>
    <collision>
      <origin rpy="0 0 0" xyz="0 0 0" />
      <geometry>
        <box size="0.022 0.00635 0.0375" />
      </geometry>
      <material name="">
        <color rgba="0.9 0.0 0.0 1" />
      </material>
    </collision>
  </link>
  <link name="arm_2_left_inner_knuckle">
    <inertial>
      <origin rpy="0 0 0" xyz="0.000123011831763771 0.0507850843201817 0.00103968640075166" />
      <mass value="0.0271177346495152" />
      <inertia ixx="2.61910379223783E-05" ixy="-2.43616858946494E-07" ixz="-6.37789906117123E-09" iyy="2.8270243746167E-06" iyz="-5.37200748039765E-07" izz="2.83695868220296E-05" />
    </inertial>
    <visual>
      <origin rpy="0 0 0" xyz="0 0 0" />
      <geometry>
        <mesh filename="../curobo/src/curobo/content/assets/robot/kinova/kortex_description/grippers/robotiq_2f_85/meshes/visual/robotiq_arg2f_85_inner_knuckle.dae" scale="0.001 0.001 0.001" />
      </geometry>
      <material name="">
        <color rgba="0.1 0.1 0.1 1" />
      </material>
    </visual>
    <collision>
      <origin rpy="0 0 0" xyz="0 0 0" />
      <geometry>
        <mesh filename="../curobo/src/curobo/content/assets/robot/kinova/kortex_description/grippers/robotiq_2f_85/meshes/collision/robotiq_arg2f_85_inner_knuckle.dae" scale="0.001 0.001 0.001" />
      </geometry>
    </collision>
  </link>
  <link name="arm_2_right_outer_knuckle">
    <inertial>
      <origin rpy="0 0 0" xyz="-0.000200000000003065 0.0199435877845359 0.0292245259211331" />
      <mass value="0.00853198276973456" />
      <inertia ixx="2.89328108496468E-06" ixy="-1.57935047237397E-19" ixz="-1.93980378593255E-19" iyy="1.86719750325683E-06" iyz="-1.21858577871576E-06" izz="1.21905238907251E-06" />
    </inertial>
    <visual>
      <origin rpy="0 0 0" xyz="0 0 0" />
      <geometry>
        <mesh filename="../curobo/src/curobo/content/assets/robot/kinova/kortex_description/grippers/robotiq_2f_85/meshes/visual/robotiq_arg2f_85_outer_knuckle.dae" scale="0.001 0.001 0.001" />
      </geometry>
      <material name="">
        <color rgba="0.792156862745098 0.819607843137255 0.933333333333333 1" />
      </material>
    </visual>
    <collision>
      <origin rpy="0 0 0" xyz="0 0 0" />
      <geometry>
        <mesh filename="../curobo/src/curobo/content/assets/robot/kinova/kortex_description/grippers/robotiq_2f_85/meshes/collision/robotiq_arg2f_85_outer_knuckle.dae" scale="0.001 0.001 0.001" />
      </geometry>
    </collision>
  </link>
  <link name="arm_2_right_outer_finger">
    <inertial>
      <origin rpy="0 0 0" xyz="0.00030115855001899 0.0373907951953854 -0.0208027427000385" />
      <mass value="0.022614240507152" />
      <inertia ixx="1.52518312458174E-05" ixy="9.76583423954399E-10" ixz="-5.43838577022588E-10" iyy="6.17694243867776E-06" iyz="6.78636130740228E-06" izz="1.16494917907219E-05" />
    </inertial>
    <visual>
      <origin rpy="0 0 0" xyz="0 0 0" />
      <geometry>
        <mesh filename="../curobo/src/curobo/content/assets/robot/kinova/kortex_description/grippers/robotiq_2f_85/meshes/visual/robotiq_arg2f_85_outer_finger.dae" scale="0.001 0.001 0.001" />
      </geometry>
      <material name="">
        <color rgba="0.1 0.1 0.1 1" />
      </material>
    </visual>
    <collision>
      <origin rpy="0 0 0" xyz="0 0 0" />
      <geometry>
        <mesh filename="../curobo/src/curobo/content/assets/robot/kinova/kortex_description/grippers/robotiq_2f_85/meshes/collision/robotiq_arg2f_85_outer_finger.dae" scale="0.001 0.001 0.001" />
      </geometry>
    </collision>
  </link>
  <link name="arm_2_right_inner_finger">
    <inertial>
      <origin rpy="0 0 0" xyz="0.000299999999999317 0.0160078233491243 -0.0136945669206257" />
      <mass value="0.0104003125914103" />
      <inertia ixx="2.71909453810972E-06" ixy="1.35402465472579E-21" ixz="-7.1817349065269E-22" iyy="7.69100314106116E-07" iyz="6.74715432769696E-07" izz="2.30315190420171E-06" />
    </inertial>
    <visual>
      <origin rpy="0 0 0" xyz="0 0 0" />
      <geometry>
        <mesh filename="../curobo/src/curobo/content/assets/robot/kinova/kortex_description/grippers/robotiq_2f_85/meshes/visual/robotiq_arg2f_85_inner_finger.dae" scale="0.001 0.001 0.001" />
      </geometry>
      <material name="">
        <color rgba="0.1 0.1 0.1 1" />
      </material>
    </visual>
    <collision>
      <origin rpy="0 0 0" xyz="0 0 0" />
      <geometry>
        <mesh filename="../curobo/src/curobo/content/assets/robot/kinova/kortex_description/grippers/robotiq_2f_85/meshes/collision/robotiq_arg2f_85_inner_finger.dae" scale="0.001 0.001 0.001" />
      </geometry>
    </collision>
  </link>
  <link name="arm_2_right_inner_finger_pad">
    <visual>
      <origin rpy="0 0 0" xyz="0 0 0" />
      <geometry>
        <box size="0.022 0.00635 0.0375" />
      </geometry>
      <material name="">
        <color rgba="0.9 0.9 0.9 1" />
      </material>
    </visual>
    <collision>
      <origin rpy="0 0 0" xyz="0 0 0" />
      <geometry>
        <box size="0.022 0.00635 0.0375" />
      </geometry>
      <material name="">
        <color rgba="0.9 0.0 0.0 1" />
      </material>
    </collision>
  </link>
  <link name="arm_2_right_inner_knuckle">
    <inertial>
      <origin rpy="0 0 0" xyz="0.000123011831763771 0.0507850843201817 0.00103968640075166" />
      <mass value="0.0271177346495152" />
      <inertia ixx="2.61910379223783E-05" ixy="-2.43616858946494E-07" ixz="-6.37789906117123E-09" iyy="2.8270243746167E-06" iyz="-5.37200748039765E-07" izz="2.83695868220296E-05" />
    </inertial>
    <visual>
      <origin rpy="0 0 0" xyz="0 0 0" />
      <geometry>
        <mesh filename="../curobo/src/curobo/content/assets/robot/kinova/kortex_description/grippers/robotiq_2f_85/meshes/visual/robotiq_arg2f_85_inner_knuckle.dae" scale="0.001 0.001 0.001" />
      </geometry>
      <material name="">
        <color rgba="0.1 0.1 0.1 1" />
      </material>
    </visual>
    <collision>
      <origin rpy="0 0 0" xyz="0 0 0" />
      <geometry>
        <mesh filename="../curobo/src/curobo/content/assets/robot/kinova/kortex_description/grippers/robotiq_2f_85/meshes/collision/robotiq_arg2f_85_inner_knuckle.dae" scale="0.001 0.001 0.001" />
      </geometry>
    </collision>
  </link>
  <joint name="arm_2_left_outer_knuckle_joint" type="fixed">
    <origin rpy="0 0 3.1415" xyz="0 -0.0306011 0.054904" />
    <parent link="arm_2_robotiq_arg2f_base_link" />
    <child link="arm_2_left_outer_knuckle" />
  </joint>
  <joint name="arm_2_left_outer_finger_joint" type="fixed">
    <origin rpy="0 0 0" xyz="0 0.0315 -0.0041" />
    <parent link="arm_2_left_outer_knuckle" />
    <child link="arm_2_left_outer_finger" />
  </joint>
  <joint name="arm_2_left_inner_knuckle_joint" type="fixed">
    <origin rpy="0 0 3.141592653589793" xyz="0 -0.0127 0.06142" />
    <parent link="arm_2_robotiq_arg2f_base_link" />
    <child link="arm_2_left_inner_knuckle" />
  </joint>
  <joint name="arm_2_left_inner_finger_joint" type="fixed">
    <origin rpy="0 0 0" xyz="0 0.0061 0.0471" />
    <parent link="arm_2_left_outer_finger" />
    <child link="arm_2_left_inner_finger" />
  </joint>
  <joint name="arm_2_left_inner_finger_pad_joint" type="fixed">
    <origin rpy="0 0 0" xyz="0 -0.0220203446692936 0.03242" />
    <parent link="arm_2_left_inner_finger" />
    <child link="arm_2_left_inner_finger_pad" />
  </joint>
  <joint name="arm_2_right_outer_knuckle_joint" type="fixed">
    <origin rpy="0 0 0" xyz="0 0.0306011 0.054904" />
    <parent link="arm_2_robotiq_arg2f_base_link" />
    <child link="arm_2_right_outer_knuckle" />
    <axis xyz="1 0 0" />
    <limit effort="1000" lower="0" upper="0.8" velocity="2.0" />
  </joint>
  <joint name="arm_2_right_outer_finger_joint" type="fixed">
    <origin rpy="0 0 0" xyz="0 0.0315 -0.0041" />
    <parent link="arm_2_right_outer_knuckle" />
    <child link="arm_2_right_outer_finger" />
  </joint>
  <joint name="arm_2_right_inner_knuckle_joint" type="fixed">
    <origin rpy="0 0 0.0" xyz="0 0.0127 0.06142" />
    <parent link="arm_2_robotiq_arg2f_base_link" />
    <child link="arm_2_right_inner_knuckle" />
  </joint>
  <joint name="arm_2_right_inner_finger_joint" type="fixed">
    <origin rpy="0 0 0" xyz="0 0.0061 0.0471" />
    <parent link="arm_2_right_outer_finger" />
    <child link="arm_2_right_inner_finger" />
  </joint>
  <joint name="arm_2_right_inner_finger_pad_joint" type="fixed">
    <origin rpy="0 0 0" xyz="0 -0.0220203446692936 0.03242" />
    <parent link="arm_2_right_inner_finger" />
    <child link="arm_2_right_inner_finger_pad" />
  </joint>
</robot>