<?xml version="1.0" ?>
<robot name="simple_disk">

  <!-- World link (virtual anchor) -->
  <link name="world">
    <inertial>
      <origin xyz="0 0 0" rpy="0 0 0"/>
      <mass value="0.001"/>
      <inertia ixx="1e-6" ixy="0" ixz="0" iyy="1e-6" iyz="0" izz="1e-6"/>
    </inertial>
  </link>

  <!-- Intermediate link for X movement -->
  <link name="intermediate">
    <inertial>
      <origin xyz="0 0 0" rpy="0 0 0"/>
      <mass value="0.001"/>
      <inertia ixx="1e-6" ixy="0" ixz="0" iyy="1e-6" iyz="0" izz="1e-6"/>
    </inertial>
  </link>

  <!-- Main robot disk -->
  <link name="base_link">
    <visual>
      <origin xyz="0 0 0.01" rpy="0 0 0"/>
      <geometry>
        <cylinder radius="0.025" length="0.02"/>
      </geometry>
      <material name="red_material">
        <color rgba="1.0 0.0 0.0 1.0"/>
      </material>
    </visual>
    <collision>
      <origin xyz="0 0 0.05" rpy="0 0 0"/>
      <geometry>
        <cylinder radius="0.025" length="0.01"/>
      </geometry>
    </collision>
    <inertial>
      <origin xyz="0 0 0.01" rpy="0 0 0"/>
      <mass value="0.5"/>
      <inertia ixx="0.015" ixy="0" ixz="0" iyy="0.015" iyz="0" izz="0.0225"/>
    </inertial>
  </link>

  <!-- End-effector reference point -->
  <link name="ee_link">
    <inertial>
      <origin xyz="0 0 0" rpy="0 0 0"/>
      <mass value="0.001"/>
      <inertia ixx="1e-6" ixy="0" ixz="0" iyy="1e-6" iyz="0" izz="1e-6"/>
    </inertial>
  </link>

  <!-- Prismatic joint for X movement -->
  <joint name="joint_x" type="prismatic">
    <parent link="world"/>
    <child link="intermediate"/>
    <origin xyz="0 0 0" rpy="0 0 0"/>
    <axis xyz="1 0 0"/>
    <limit lower="-100" upper="100" velocity="1.0" effort="1"/>
    <dynamics damping="1.0"/>
  </joint>

  <!-- Prismatic joint for Y movement -->
  <joint name="joint_y" type="prismatic">
    <parent link="intermediate"/>
    <child link="base_link"/>
    <origin xyz="0 0 0" rpy="0 0 0"/>
    <axis xyz="0 1 0"/>
    <limit lower="-100" upper="100" velocity="1.0" effort="1"/>
    <dynamics damping="1.0"/>
  </joint>

  <!-- Fixed joint to end-effector -->
  <joint name="base_to_ee" type="fixed">
    <origin xyz="0 0 0" rpy="0 0 0"/>
    <parent link="base_link"/>
    <child link="ee_link"/>
  </joint>

</robot>
